<?xml version="1.0"?>
<robot name="body" xmlns:xacro="http://ros.org/wiki/xacro">

  <xacro:macro name="premaidai_body" params="parent *origin">

    <link name="body">
      <visual>
        <geometry>
            <mesh filename="package://premaidai_description/meshes/body.dae"/>
        </geometry>
      </visual>
      <collision>
        <geometry>
            <mesh filename="package://premaidai_description/meshes/body.dae"/>
        </geometry>
      </collision>
    </link>

    <link name="neck">
      <visual>
        <geometry>
            <mesh filename="package://premaidai_description/meshes/neck.dae"/>
        </geometry>
      </visual>
      <collision>
        <geometry>
            <mesh filename="package://premaidai_description/meshes/neck.dae"/>
        </geometry>
      </collision>
    </link>

    <link name="head_dummy">
      <visual>
        <geometry>
          <box size="0.01 0.01 0.01" />
        </geometry>
      </visual>
    </link>

    <link name="head">
      <visual>
        <geometry>
            <mesh filename="package://premaidai_description/meshes/head.dae"/>
        </geometry>
      </visual>
      <collision>
        <geometry>
            <mesh filename="package://premaidai_description/meshes/head.dae"/>
        </geometry>
      </collision>
    </link>

    <joint name="body_to_base_link" type="fixed">
      <origin xyz="0.0236 0 0" rpy="0 0 0"/>
      <parent link="${parent}"/>
      <child link="body"/>
    </joint>

    <joint name="head_ny_joint" type="revolute">
      <origin xyz="-0.0319 0 0.1088" rpy="0 0 0"/>
      <axis xyz="0 1 0"/>
      <limit lower="${-pi/2.0}" upper="${pi/2.0}" effort="0" velocity="0"/>
      <parent link="body"/>
      <child link="neck"/>
    </joint>

    <joint name="head_nz_joint" type="revolute">
      <origin xyz="0 0 0" rpy="0 0 0"/>
      <axis xyz="0 0 1"/>
      <limit lower="${-pi/2.0}" upper="${pi/2.0}" effort="0" velocity="0"/>
      <parent link="neck"/>
      <child link="head_dummy"/>
    </joint>

    <joint name="head_nx_joint" type="revolute">
      <origin xyz="0 0 0.0362" rpy="0 0 0"/>
      <axis xyz="1 0 0"/>
      <limit lower="${-pi/2.0}" upper="${pi/2.0}" effort="0" velocity="0"/>
      <parent link="head_dummy"/>
      <child link="head"/>
    </joint>

<!-- MUST implement
    <joint name="head_yaw_joint" type="revolute">
      <origin xyz="0 0 0.0362" rpy="0 0 0"/>
      <axis xyz="0 1 0"/>
      <limit lower="0" upper="0" effort="0" velocity="0"/>
      <parent link="neck"/>
      <child link="head"/>
    </joint>
 -->

  </xacro:macro>
</robot>