<?xml version="1.0"?>
<robot name="body" xmlns:xacro="http://ros.org/wiki/xacro">

  <xacro:macro name="premaidai_body" params="parent *origin">

    <link name="body">
      <visual>
        <geometry>
          <mesh filename="package://premaidai_description/meshes/body.dae"/>
        </geometry>
      </visual>
      <collision>
        <geometry>
          <mesh filename="package://premaidai_description/meshes/body.dae"/>
        </geometry>
      </collision>
    </link>

    <link name="neck_pitch">
      <visual>
        <geometry>
          <mesh filename="package://premaidai_description/meshes/neck_pitch.dae"/>
        </geometry>
      </visual>
      <collision>
        <geometry>
          <mesh filename="package://premaidai_description/meshes/neck_pitch.dae"/>
        </geometry>
      </collision>
    </link>

    <link name="head_yaw">
      <visual>
        <geometry>
          <mesh filename="package://premaidai_description/meshes/neck_yaw.dae"/>
        </geometry>
      </visual>
      <collision>
        <geometry>
          <mesh filename="package://premaidai_description/meshes/neck_yaw.dae"/>
        </geometry>
      </collision>
    </link>

    <link name="head">
      <visual>
        <geometry>
          <mesh filename="package://premaidai_description/meshes/head.dae"/>
        </geometry>
      </visual>
      <collision>
        <geometry>
          <mesh filename="package://premaidai_description/meshes/head.dae"/>
        </geometry>
      </collision>
    </link>

    <joint name="body_to_base_link" type="fixed">
      <origin xyz="0 0 0" rpy="0 0 0"/>
      <parent link="${parent}"/>
      <child link="body"/>
    </joint>

    <joint name="head_ny_joint" type="revolute">
      <origin xyz="0.0038738 0 0.132809" rpy="0 0 0"/>
      <axis xyz="0 1 0"/>
      <limit lower="${-10.125/180.0 * pi}" upper="${23.625/180.0 * pi}" effort="0" velocity="0"/>
      <parent link="body"/>
      <child link="neck_pitch"/>
    </joint>

    <joint name="head_nz_joint" type="revolute">
      <origin xyz="-0.0103485 0 0.011103" rpy="0 0 0"/>
      <axis xyz="0 0 1"/>
      <limit lower="${-47.25/180.0 * pi}" upper="${47.25/180.0 * pi}" effort="0" velocity="0"/>
      <parent link="neck_pitch"/>
      <child link="head_yaw"/>
    </joint>

    <joint name="head_nx_joint" type="revolute">
      <origin xyz="0 0 0.0129" rpy="0 0 0"/>
      <axis xyz="1 0 0"/>
      <limit lower="${-21.9375/180.0 * pi}" upper="${28.6875/180.0 * pi}" effort="0" velocity="0"/>
      <parent link="head_yaw"/>
      <child link="head"/>
    </joint>
  </xacro:macro>
</robot>